2024-05-02 14:11:03,819 INFO    StreamThr :43977 [internal.py:wandb_internal():86] W&B internal server running at pid: 43977, started at: 2024-05-02 14:11:03.818867
2024-05-02 14:11:03,820 DEBUG   HandlerThread:43977 [handler.py:handle_request():146] handle_request: status
2024-05-02 14:11:03,821 INFO    WriterThread:43977 [datastore.py:open_for_write():87] open: /home/radoslavralev/Documents/Thesis/gfn-diffusion/energy_sampling/wandb/run-20240502_141103-5wt1x5ze/run-5wt1x5ze.wandb
2024-05-02 14:11:03,821 DEBUG   SenderThread:43977 [sender.py:send():379] send: header
2024-05-02 14:11:03,840 DEBUG   SenderThread:43977 [sender.py:send():379] send: run
2024-05-02 14:11:08,841 DEBUG   HandlerThread:43977 [handler.py:handle_request():146] handle_request: keepalive
2024-05-02 14:11:13,843 DEBUG   HandlerThread:43977 [handler.py:handle_request():146] handle_request: keepalive
2024-05-02 14:11:18,844 DEBUG   HandlerThread:43977 [handler.py:handle_request():146] handle_request: keepalive
2024-05-02 14:11:23,845 DEBUG   HandlerThread:43977 [handler.py:handle_request():146] handle_request: keepalive
2024-05-02 14:11:28,846 DEBUG   HandlerThread:43977 [handler.py:handle_request():146] handle_request: keepalive
2024-05-02 14:11:33,847 DEBUG   HandlerThread:43977 [handler.py:handle_request():146] handle_request: keepalive
2024-05-02 14:11:38,849 DEBUG   HandlerThread:43977 [handler.py:handle_request():146] handle_request: keepalive
2024-05-02 14:11:43,850 DEBUG   HandlerThread:43977 [handler.py:handle_request():146] handle_request: keepalive
2024-05-02 14:11:48,852 DEBUG   HandlerThread:43977 [handler.py:handle_request():146] handle_request: keepalive
2024-05-02 14:11:53,853 DEBUG   HandlerThread:43977 [handler.py:handle_request():146] handle_request: keepalive
2024-05-02 14:11:58,854 DEBUG   HandlerThread:43977 [handler.py:handle_request():146] handle_request: keepalive
2024-05-02 14:12:03,856 DEBUG   HandlerThread:43977 [handler.py:handle_request():146] handle_request: keepalive
2024-05-02 14:12:07,855 INFO    SenderThread:43977 [retry.py:__call__():172] Retry attempt failed:
Traceback (most recent call last):
  File "/home/radoslavralev/miniconda3/envs/gfn-diffusion/lib/python3.8/site-packages/urllib3/connectionpool.py", line 536, in _make_request
    response = conn.getresponse()
  File "/home/radoslavralev/miniconda3/envs/gfn-diffusion/lib/python3.8/site-packages/urllib3/connection.py", line 461, in getresponse
    httplib_response = super().getresponse()
  File "/home/radoslavralev/miniconda3/envs/gfn-diffusion/lib/python3.8/http/client.py", line 1348, in getresponse
    response.begin()
  File "/home/radoslavralev/miniconda3/envs/gfn-diffusion/lib/python3.8/http/client.py", line 316, in begin
    version, status, reason = self._read_status()
  File "/home/radoslavralev/miniconda3/envs/gfn-diffusion/lib/python3.8/http/client.py", line 277, in _read_status
    line = str(self.fp.readline(_MAXLINE + 1), "iso-8859-1")
  File "/home/radoslavralev/miniconda3/envs/gfn-diffusion/lib/python3.8/socket.py", line 669, in readinto
    return self._sock.recv_into(b)
  File "/home/radoslavralev/miniconda3/envs/gfn-diffusion/lib/python3.8/ssl.py", line 1274, in recv_into
    return self.read(nbytes, buffer)
  File "/home/radoslavralev/miniconda3/envs/gfn-diffusion/lib/python3.8/ssl.py", line 1132, in read
    return self._sslobj.read(len, buffer)
socket.timeout: The read operation timed out

The above exception was the direct cause of the following exception:

Traceback (most recent call last):
  File "/home/radoslavralev/miniconda3/envs/gfn-diffusion/lib/python3.8/site-packages/requests/adapters.py", line 486, in send
    resp = conn.urlopen(
  File "/home/radoslavralev/miniconda3/envs/gfn-diffusion/lib/python3.8/site-packages/urllib3/connectionpool.py", line 844, in urlopen
    retries = retries.increment(
  File "/home/radoslavralev/miniconda3/envs/gfn-diffusion/lib/python3.8/site-packages/urllib3/util/retry.py", line 470, in increment
    raise reraise(type(error), error, _stacktrace)
  File "/home/radoslavralev/miniconda3/envs/gfn-diffusion/lib/python3.8/site-packages/urllib3/util/util.py", line 39, in reraise
    raise value
  File "/home/radoslavralev/miniconda3/envs/gfn-diffusion/lib/python3.8/site-packages/urllib3/connectionpool.py", line 790, in urlopen
    response = self._make_request(
  File "/home/radoslavralev/miniconda3/envs/gfn-diffusion/lib/python3.8/site-packages/urllib3/connectionpool.py", line 538, in _make_request
    self._raise_timeout(err=e, url=url, timeout_value=read_timeout)
  File "/home/radoslavralev/miniconda3/envs/gfn-diffusion/lib/python3.8/site-packages/urllib3/connectionpool.py", line 370, in _raise_timeout
    raise ReadTimeoutError(
urllib3.exceptions.ReadTimeoutError: HTTPSConnectionPool(host='api.wandb.ai', port=443): Read timed out. (read timeout=20)

During handling of the above exception, another exception occurred:

Traceback (most recent call last):
  File "/home/radoslavralev/miniconda3/envs/gfn-diffusion/lib/python3.8/site-packages/wandb/sdk/lib/retry.py", line 131, in __call__
    result = self._call_fn(*args, **kwargs)
  File "/home/radoslavralev/miniconda3/envs/gfn-diffusion/lib/python3.8/site-packages/wandb/sdk/internal/internal_api.py", line 369, in execute
    return self.client.execute(*args, **kwargs)  # type: ignore
  File "/home/radoslavralev/miniconda3/envs/gfn-diffusion/lib/python3.8/site-packages/wandb/vendor/gql-0.2.0/wandb_gql/client.py", line 52, in execute
    result = self._get_result(document, *args, **kwargs)
  File "/home/radoslavralev/miniconda3/envs/gfn-diffusion/lib/python3.8/site-packages/wandb/vendor/gql-0.2.0/wandb_gql/client.py", line 60, in _get_result
    return self.transport.execute(document, *args, **kwargs)
  File "/home/radoslavralev/miniconda3/envs/gfn-diffusion/lib/python3.8/site-packages/wandb/sdk/lib/gql_request.py", line 58, in execute
    request = self.session.post(self.url, **post_args)
  File "/home/radoslavralev/miniconda3/envs/gfn-diffusion/lib/python3.8/site-packages/requests/sessions.py", line 637, in post
    return self.request("POST", url, data=data, json=json, **kwargs)
  File "/home/radoslavralev/miniconda3/envs/gfn-diffusion/lib/python3.8/site-packages/requests/sessions.py", line 589, in request
    resp = self.send(prep, **send_kwargs)
  File "/home/radoslavralev/miniconda3/envs/gfn-diffusion/lib/python3.8/site-packages/requests/sessions.py", line 703, in send
    r = adapter.send(request, **kwargs)
  File "/home/radoslavralev/miniconda3/envs/gfn-diffusion/lib/python3.8/site-packages/requests/adapters.py", line 532, in send
    raise ReadTimeout(e, request=request)
requests.exceptions.ReadTimeout: HTTPSConnectionPool(host='api.wandb.ai', port=443): Read timed out. (read timeout=20)
2024-05-02 14:12:08,857 DEBUG   HandlerThread:43977 [handler.py:handle_request():146] handle_request: keepalive
2024-05-02 14:12:13,859 DEBUG   HandlerThread:43977 [handler.py:handle_request():146] handle_request: keepalive
2024-05-02 14:12:15,794 DEBUG   HandlerThread:43977 [handler.py:handle_request():146] handle_request: shutdown
2024-05-02 14:12:15,794 INFO    HandlerThread:43977 [handler.py:finish():866] shutting down handler
2024-05-02 14:12:15,855 INFO    WriterThread:43977 [datastore.py:close():296] close: /home/radoslavralev/Documents/Thesis/gfn-diffusion/energy_sampling/wandb/run-20240502_141103-5wt1x5ze/run-5wt1x5ze.wandb
2024-05-02 14:12:49,381 INFO    SenderThread:43977 [dir_watcher.py:__init__():211] watching files in: /home/radoslavralev/Documents/Thesis/gfn-diffusion/energy_sampling/wandb/run-20240502_141103-5wt1x5ze/files
2024-05-02 14:12:49,381 INFO    SenderThread:43977 [sender.py:_start_run_threads():1124] run started: 5wt1x5ze with start time 1714651863.818904
2024-05-02 14:12:49,381 INFO    SenderThread:43977 [sender.py:finish():1546] shutting down sender
2024-05-02 14:12:49,381 INFO    SenderThread:43977 [dir_watcher.py:finish():358] shutting down directory watcher
2024-05-02 14:12:50,381 INFO    SenderThread:43977 [dir_watcher.py:finish():388] scan: /home/radoslavralev/Documents/Thesis/gfn-diffusion/energy_sampling/wandb/run-20240502_141103-5wt1x5ze/files
2024-05-02 14:12:50,382 INFO    SenderThread:43977 [dir_watcher.py:finish():402] scan save: /home/radoslavralev/Documents/Thesis/gfn-diffusion/energy_sampling/wandb/run-20240502_141103-5wt1x5ze/files/config.yaml config.yaml
2024-05-02 14:12:50,382 INFO    SenderThread:43977 [file_pusher.py:finish():172] shutting down file pusher
2024-05-02 14:12:50,382 INFO    SenderThread:43977 [file_pusher.py:join():178] waiting for file pusher
2024-05-02 14:12:52,167 INFO    wandb-upload_0:43977 [upload_job.py:push():131] Uploaded file /home/radoslavralev/Documents/Thesis/gfn-diffusion/energy_sampling/wandb/run-20240502_141103-5wt1x5ze/files/config.yaml
2024-05-02 14:12:52,384 INFO    SenderThread:43977 [file_stream.py:finish():614] file stream finish called
2024-05-02 14:12:53,457 INFO    SenderThread:43977 [file_stream.py:finish():618] file stream finish is done
