2024-05-02 14:08:37,590 INFO    MainThread:43076 [wandb_setup.py:_flush():76] Current SDK version is 0.16.6
2024-05-02 14:08:37,590 INFO    MainThread:43076 [wandb_setup.py:_flush():76] Configure stats pid to 43076
2024-05-02 14:08:37,590 INFO    MainThread:43076 [wandb_setup.py:_flush():76] Loading settings from /home/radoslavralev/.config/wandb/settings
2024-05-02 14:08:37,590 INFO    MainThread:43076 [wandb_setup.py:_flush():76] Loading settings from /home/radoslavralev/Documents/Thesis/gfn-diffusion/energy_sampling/wandb/settings
2024-05-02 14:08:37,590 INFO    MainThread:43076 [wandb_setup.py:_flush():76] Loading settings from environment variables: {}
2024-05-02 14:08:37,590 INFO    MainThread:43076 [wandb_setup.py:_flush():76] Applying setup settings: {'_disable_service': False}
2024-05-02 14:08:37,590 INFO    MainThread:43076 [wandb_setup.py:_flush():76] Inferring run settings from compute environment: {'program_relpath': 'energy_sampling/train.py', 'program_abspath': '/home/radoslavralev/Documents/Thesis/gfn-diffusion/energy_sampling/train.py', 'program': 'train.py'}
2024-05-02 14:08:37,590 INFO    MainThread:43076 [wandb_setup.py:_flush():76] Applying login settings: {}
2024-05-02 14:08:37,590 INFO    MainThread:43076 [wandb_init.py:_log_setup():521] Logging user logs to /home/radoslavralev/Documents/Thesis/gfn-diffusion/energy_sampling/wandb/run-20240502_140837-efxxdwgg/logs/debug.log
2024-05-02 14:08:37,591 INFO    MainThread:43076 [wandb_init.py:_log_setup():522] Logging internal logs to /home/radoslavralev/Documents/Thesis/gfn-diffusion/energy_sampling/wandb/run-20240502_140837-efxxdwgg/logs/debug-internal.log
2024-05-02 14:08:37,591 INFO    MainThread:43076 [wandb_init.py:init():561] calling init triggers
2024-05-02 14:08:37,591 INFO    MainThread:43076 [wandb_init.py:init():568] wandb.init called with sweep_config: {}
config: {'lr_policy': 0.001, 'lr_flow': 0.1, 'lr_back': 0.001, 'hidden_dim': 64, 's_emb_dim': 64, 't_emb_dim': 64, 'harmonics_dim': 64, 'batch_size': 300, 'epochs': 25000, 'buffer_size': 600000, 'T': 100, 'subtb_lambda': 2, 't_scale': 1.0, 'log_var_range': 4.0, 'energy': 'alanine_vacuum_source', 'mode_fwd': 'tb', 'mode_bwd': 'tb', 'both_ways': False, 'local_search': False, 'max_iter_ls': 200, 'burn_in': 100, 'ls_cycle': 100, 'ld_step': 0.001, 'ld_schedule': False, 'target_acceptance_rate': 0.574, 'beta': 1.0, 'rank_weight': 0.01, 'prioritized': 'rank', 'bwd': False, 'exploratory': False, 'sampling': 'buffer', 'langevin': False, 'langevin_scaling_per_dimension': False, 'conditional_flow_model': False, 'learn_pb': False, 'pb_scale_range': 0.1, 'learned_variance': False, 'partial_energy': False, 'exploration_factor': 0.1, 'exploration_wd': False, 'clipping': True, 'lgv_clip': 100.0, 'gfn_clip': 10000.0, 'zero_init': True, 'pis_architectures': True, 'lgv_layers': 3, 'joint_layers': 2, 'seed': 12345, 'weight_decay': 1e-07, 'use_weight_decay': False, 'eval': False, 'Experiment': '{args.energy}'}
2024-05-02 14:08:37,591 INFO    MainThread:43076 [wandb_init.py:init():611] starting backend
2024-05-02 14:08:37,591 INFO    MainThread:43076 [wandb_init.py:init():615] setting up manager
2024-05-02 14:08:37,592 INFO    MainThread:43076 [backend.py:_multiprocessing_setup():105] multiprocessing start_methods=fork,spawn,forkserver, using: spawn
2024-05-02 14:08:37,593 INFO    MainThread:43076 [wandb_init.py:init():623] backend started and connected
2024-05-02 14:08:37,597 INFO    MainThread:43076 [wandb_init.py:init():715] updated telemetry
2024-05-02 14:08:37,629 INFO    MainThread:43076 [wandb_init.py:init():748] communicating run to backend with 90.0 second timeout
2024-05-02 14:09:36,291 INFO    Thread-1  :43076 [retry.py:__call__():172] Retry attempt failed:
Traceback (most recent call last):
  File "/home/radoslavralev/miniconda3/envs/gfn-diffusion/lib/python3.8/site-packages/urllib3/connectionpool.py", line 536, in _make_request
    response = conn.getresponse()
  File "/home/radoslavralev/miniconda3/envs/gfn-diffusion/lib/python3.8/site-packages/urllib3/connection.py", line 461, in getresponse
    httplib_response = super().getresponse()
  File "/home/radoslavralev/miniconda3/envs/gfn-diffusion/lib/python3.8/http/client.py", line 1348, in getresponse
    response.begin()
  File "/home/radoslavralev/miniconda3/envs/gfn-diffusion/lib/python3.8/http/client.py", line 316, in begin
    version, status, reason = self._read_status()
  File "/home/radoslavralev/miniconda3/envs/gfn-diffusion/lib/python3.8/http/client.py", line 277, in _read_status
    line = str(self.fp.readline(_MAXLINE + 1), "iso-8859-1")
  File "/home/radoslavralev/miniconda3/envs/gfn-diffusion/lib/python3.8/socket.py", line 669, in readinto
    return self._sock.recv_into(b)
  File "/home/radoslavralev/miniconda3/envs/gfn-diffusion/lib/python3.8/ssl.py", line 1274, in recv_into
    return self.read(nbytes, buffer)
  File "/home/radoslavralev/miniconda3/envs/gfn-diffusion/lib/python3.8/ssl.py", line 1132, in read
    return self._sslobj.read(len, buffer)
socket.timeout: The read operation timed out

The above exception was the direct cause of the following exception:

Traceback (most recent call last):
  File "/home/radoslavralev/miniconda3/envs/gfn-diffusion/lib/python3.8/site-packages/requests/adapters.py", line 486, in send
    resp = conn.urlopen(
  File "/home/radoslavralev/miniconda3/envs/gfn-diffusion/lib/python3.8/site-packages/urllib3/connectionpool.py", line 844, in urlopen
    retries = retries.increment(
  File "/home/radoslavralev/miniconda3/envs/gfn-diffusion/lib/python3.8/site-packages/urllib3/util/retry.py", line 470, in increment
    raise reraise(type(error), error, _stacktrace)
  File "/home/radoslavralev/miniconda3/envs/gfn-diffusion/lib/python3.8/site-packages/urllib3/util/util.py", line 39, in reraise
    raise value
  File "/home/radoslavralev/miniconda3/envs/gfn-diffusion/lib/python3.8/site-packages/urllib3/connectionpool.py", line 790, in urlopen
    response = self._make_request(
  File "/home/radoslavralev/miniconda3/envs/gfn-diffusion/lib/python3.8/site-packages/urllib3/connectionpool.py", line 538, in _make_request
    self._raise_timeout(err=e, url=url, timeout_value=read_timeout)
  File "/home/radoslavralev/miniconda3/envs/gfn-diffusion/lib/python3.8/site-packages/urllib3/connectionpool.py", line 370, in _raise_timeout
    raise ReadTimeoutError(
urllib3.exceptions.ReadTimeoutError: HTTPSConnectionPool(host='api.wandb.ai', port=443): Read timed out. (read timeout=20)

During handling of the above exception, another exception occurred:

Traceback (most recent call last):
  File "/home/radoslavralev/miniconda3/envs/gfn-diffusion/lib/python3.8/site-packages/wandb/sdk/lib/retry.py", line 131, in __call__
    result = self._call_fn(*args, **kwargs)
  File "/home/radoslavralev/miniconda3/envs/gfn-diffusion/lib/python3.8/site-packages/wandb/sdk/internal/internal_api.py", line 369, in execute
    return self.client.execute(*args, **kwargs)  # type: ignore
  File "/home/radoslavralev/miniconda3/envs/gfn-diffusion/lib/python3.8/site-packages/wandb/vendor/gql-0.2.0/wandb_gql/client.py", line 52, in execute
    result = self._get_result(document, *args, **kwargs)
  File "/home/radoslavralev/miniconda3/envs/gfn-diffusion/lib/python3.8/site-packages/wandb/vendor/gql-0.2.0/wandb_gql/client.py", line 60, in _get_result
    return self.transport.execute(document, *args, **kwargs)
  File "/home/radoslavralev/miniconda3/envs/gfn-diffusion/lib/python3.8/site-packages/wandb/sdk/lib/gql_request.py", line 58, in execute
    request = self.session.post(self.url, **post_args)
  File "/home/radoslavralev/miniconda3/envs/gfn-diffusion/lib/python3.8/site-packages/requests/sessions.py", line 637, in post
    return self.request("POST", url, data=data, json=json, **kwargs)
  File "/home/radoslavralev/miniconda3/envs/gfn-diffusion/lib/python3.8/site-packages/requests/sessions.py", line 589, in request
    resp = self.send(prep, **send_kwargs)
  File "/home/radoslavralev/miniconda3/envs/gfn-diffusion/lib/python3.8/site-packages/requests/sessions.py", line 703, in send
    r = adapter.send(request, **kwargs)
  File "/home/radoslavralev/miniconda3/envs/gfn-diffusion/lib/python3.8/site-packages/requests/adapters.py", line 532, in send
    raise ReadTimeout(e, request=request)
requests.exceptions.ReadTimeout: HTTPSConnectionPool(host='api.wandb.ai', port=443): Read timed out. (read timeout=20)
2024-05-02 14:10:07,657 ERROR   MainThread:43076 [wandb_init.py:init():774] encountered error: Run initialization has timed out after 90.0 sec. 
Please refer to the documentation for additional information: https://docs.wandb.ai/guides/track/tracking-faq#initstarterror-error-communicating-with-wandb-process-
2024-05-02 14:10:08,403 ERROR   MainThread:43076 [wandb_init.py:init():1199] Run initialization has timed out after 90.0 sec. 
Please refer to the documentation for additional information: https://docs.wandb.ai/guides/track/tracking-faq#initstarterror-error-communicating-with-wandb-process-
Traceback (most recent call last):
  File "/home/radoslavralev/miniconda3/envs/gfn-diffusion/lib/python3.8/site-packages/wandb/sdk/wandb_init.py", line 1181, in init
    run = wi.init()
  File "/home/radoslavralev/miniconda3/envs/gfn-diffusion/lib/python3.8/site-packages/wandb/sdk/wandb_init.py", line 780, in init
    raise error
wandb.errors.CommError: Run initialization has timed out after 90.0 sec. 
Please refer to the documentation for additional information: https://docs.wandb.ai/guides/track/tracking-faq#initstarterror-error-communicating-with-wandb-process-
2024-05-02 14:10:09,405 WARNING MsgRouterThr:43076 [router.py:message_loop():77] message_loop has been closed
